Workbook

Sheet Dashboard
A1: BSU REMIS - Research Publications Monitoring Dashboard
A2: Last Updated: | B2: 2026-01-27 14:05:06
A4: KEY PERFORMANCE INDICATORS
A5: Total Publications (All Years) | E5: Publications 2025
A6: =Publications_Summary!B2 -> 401 | E6: =Publications_Summary!B3 -> 54
A8: Total Faculty Tracked | E8: Avg H-Index
A9: =Faculty_Metrics!B2 -> 59 | E9: =Faculty_Metrics!B3 -> 3.3389831
A12: ALERTS & NOTIFICATIONS
A13: Alert Type | B13: Description | C13: Count | D13: Status
A14: Missing H-Index | B14: Faculty without H-index data | C14: =Faculty_Metrics!B4 -> 40 | D14: Review
A15: Low Citations | B15: Faculty with <100 citations | C15: =Faculty_Metrics!B5 -> 3 | D15: Monitor
A16: No Recent Pubs | B16: Faculty with no 2024-2025 pubs | C16: =Faculty_Metrics!B6 -> 56 | D16: Action Needed
A18: PUBLICATION TRENDS BY YEAR
A19: Year | B19: Publications
A20: 2025 | B20: =Publications_Summary!B4 -> 0
A21: 2024 | B21: =Publications_Summary!B5 -> 54
A22: 2023 | B22: =Publications_Summary!B6 -> 61
A23: 2022 | B23: =Publications_Summary!B7 -> 53
A24: 2021 | B24: =Publications_Summary!B8 -> 57
A25: 2020 | B25: =Publications_Summary!B9 -> 44
A26: 2018-2019 | B26: =Publications_Summary!B10 -> 48
A27: 2017-below | B27: =Publications_Summary!B11 -> 84

Sheet Publications_Summary
A1: PUBLICATION STATISTICS SUMMARY
A2: Total Publications (All Years) | B2: =SUM(B4:B11) -> 401
A3: Publications 2025 | B3: =COUNTA(Data_2025!D:D)-1 -> 54
A5: 2025 | B5: =COUNTA(Data_2025!D:D)-1 -> 54
A6: 2024 | B6: =COUNTA(Data_2024!D:D)-1 -> 61
A7: 2023 | B7: =COUNTA(Data_2023!D:D)-1 -> 53
A8: 2022 | B8: =COUNTA(Data_2022!D:D)-1 -> 57
A9: 2021 | B9: =COUNTA(Data_2021!D:D)-1 -> 44
A10: 2020 | B10: =COUNTA(Data_2020!D:D)-1 -> 48
A11: 2018-2019 | B11: =COUNTA(Data_2018_2019!D:D)-1 -> 84
A12: 2017 & Below | B12: =COUNTA(Data_2017_below!D:D)-1 -> 380

Sheet Faculty_Metrics
A1: FACULTY RESEARCH METRICS
A2: Total Faculty/Researchers | B2: =COUNTA(Faculty_Data!A:A)-1 -> 59
A3: Average H-Index | B3: =AVERAGEIF(Faculty_Data!C:C,">0") -> 3.3389831
A4: Missing H-Index Count | B4: =COUNTBLANK(Faculty_Data!C2:C100) -> 40
A5: Faculty with <100 Citations | B5: =COUNTIFS(Faculty_Data!B:B,"<100",Faculty_Data!B:B,">0") -> 3
A6: Faculty without Recent Pubs | B6: =B2-SUMPRODUCT((COUNTIF(Data_2024!E:E,Faculty_Data!A2:A100)>0)+(COUNTIF(Data_2025!E:E,Faculty_Data!A2:A100)>0)) -> 56

Sheet Tracking_Log
A1: PUBLICATION TRACKING LOG
A2: Date | B2: Action Type | C2: Year | D2: Publication Title | E2: Author(s) | F2: College/Institute | G2: Publication Type | H2: Status | I2: Updated By | J2: Notes
A3: 2026-01-27 | B3: Initial Setup | C3: System | D3: Monitoring system created | E3: System Admin

Sheet Faculty_Data
A1: Name | B1: Citations | C1: H-Index | D1: i-10 Index | E1: Scholar Account
A2: Roscinto Ian C. Lumbres | B2: 340 | C2: 11 | D2: 14 | E2: https://scholar.google.com/citations?user=DMax5CIAAAAJ&hl=en&oi=ao
A3: Cheryll C. Launio | B3: 588 | C3: 13 | D3: 15 | E3: https://scholar.google.com/citations?hl=en&user=Lqml6uwAAAAJ
A4: Jones Napaldet | B4: 192 | C4: 8 | D4: 7 | E4: https://scholar.google.com/citations?hl=en&user=4oMSPvIAAAAJ
A5: Sherlyn Tipayno | B5: 472 | C5: 8 | D5: 8 | E5: Sherlyn Tipayno - Google Scholar
A6: Nordalyn Pedroche | B6: 87 | C6: 5 | D6: 4 | E6: https://scholar.google.com/citations?hl=en&user=FzNIYCUAAAAJ
A7: Cynthia Garambas | C7: 2 | D7: 0 | E7: https://scholar.google.com/citations?hl=en&user=Ih7poOcAAAAJ
A8: Ruth S. Batani | C8: 3 | D8: 2 | E8: https://scholar.google.com/citations?hl=en&user=YN-qtvgAAAAJ
A9: Joyce N. Paing | C9: 3 | D9: 2 | E9: https://scholar.google.com/citations?hl=en&user=ow8JcAYAAAAJ
A10: Kenneth A. Laruan | C10: 3 | D10: 2 | E10: https://scholar.google.com/citations?hl=en&user=PyO6wrQAAAAJ
A11: Janet P. Pablo | C11: 2 | D11: 0 | E11: https://scholar.google.com/citations?hl=en&user=yAkouz0AAAAJ
A12: Jude Tayaben | B12: 554 | C12: 11 | D12: 13 | E12: https://scholar.google.com/citations?hl=en&user=P9R_wQsAAAAJ
A13: Nova D. Doyog | B13: 159 | C13: 8 | D13: 7 | E13: https://scholar.google.com/citations?hl=en&user=-WSRHRgAAAAJ
A14: Bernard Peter O. Daipan | C14: 4 | D14: 2 | E14: https://scholar.google.com/citations?hl=en&user=Wh-UtCMAAAAJ
A15: Grace S. Backian | C15: 2 | D15: 1 | E15: https://scholar.google.com/citations?hl=en&user=PA45re8AAAAJ
A16: Dalen T. Meldoz | C16: 2 | D16: 1 | E16: https://scholar.google.com/citations?hl=en&user=PA45re8AAAAJ
A17: Esther Botangen | C17: 3 | D17: 1 | E17: https://scholar.google.com/citations?hl=en&user=JVLR2AoAAAAJ
A18: Lawrence C. Caranto | B18: 535 | C18: 7 | D18: 6 | E18: https://scholar.google.com/citations?hl=en&user=mb1fOpoAAAAJ
A19: Ann Heather B. Kiwang | C19: 1 | D19: 0 | E19: https://scholar.google.com/citations?hl=en&user=hP8VWfsAAAAJ
A20: Daniel Jr. Balbin | C20: 2 | D20: 0 | E20: https://scholar.google.com/citations?hl=en&user=YXd9peYAAAAJ
A21: Marissa Parao | C21: 3 | D21: 1 | E21: https://scholar.google.com/citations?hl=en&user=KiiQ4foAAAAJ
A22: Darwin Basquial | C22: 1 | D22: 0 | E22: https://scholar.google.com/citations?hl=en&user=Vv8YJoEAAAAJ
A23: Esther Josephine D. Sagalla | C23: 2 | D23: 1 | E23: https://scholar.google.com/citations?hl=en&user=poGlUkEAAAAJ
A24: Bretel Dolipas | B24: 395 | C24: 6 | D24: 1 | E24: https://scholar.google.com/citations?hl=en&user=DREmjywAAAAJ
A25: Ronda B. Tullay | C25: 1 | D25: 0 | E25: https://scholar.google.com/citations?hl=en&user=pKmp2BYAAAAJ
A26: Marvin Valentin | B26: 211 | C26: 7 | D26: 7 | E26: https://scholar.google.com/citations?hl=en&user=8_fUSUcAAAAJ
A27: Renebeth Gatudan Donguiz | C27: 1 | D27: 0 | E27: https://scholar.google.com/citations?hl=en&user=y-L2ZTIAAAAJ
A28: John Rey Pelila | C28: 4 | D28: 1 | E28: https://scholar.google.com/citations?hl=en&user=vc_NS64AAAAJ
A29: Jhordan T. Cuilan | B29: 89 | C29: 6 | D29: 5 | E29: https://scholar.google.com/citations?hl=en&user=Y5Ot_3wAAAAJ
A30: Gleemoore C. Makie | C30: 2 | D30: 1 | E30: https://scholar.google.com/citations?hl=en&user=7OaxIsYAAAAJ
A31: Jesson Del-amen | C31: 2 | D31: 0 | E31: https://scholar.google.com/citations?hl=en&user=xuGuANoAAAAJ
A32: Teresita D. Masangcay | C32: 1 | D32: 0 | E32: https://scholar.google.com/citations?hl=en&user=MsVyn6QAAAAJ
A33: Conrado C. Bao-idang | C33: 2 | D33: 0 | E33: https://scholar.google.com/citations?hl=en&user=ekZGp3EAAAAJ
A34: Nora Hill Evasco | C34: 1 | D34: 0 | E34: https://scholar.google.com/citations?hl=en&user=I4qXom8AAAAJ
A35: Stanley F. Angonos, Jr. | C35: 1 | D35: 0 | E35: https://scholar.google.com/citations?hl=en&user=lH542fYAAAAJ
A36: Joseph B. Quinto | C36: 4 | D36: 2 | E36: https://scholar.google.com/citations?hl=en&user=hTEK3WYAAAAJ
A37: Elizabeth A. Lascano | C37: 3 | D37: 0 | E37: https://scholar.google.com/citations?hl=en&user=W67OyrcAAAAJ
A38: Divina Yango | C38: 1 | D38: 1 | E38: https://scholar.google.com/citations?hl=en&user=ep9pn1kAAAAJ
A39: Lesley Dale Umayat | C39: 1 | D39: 0 | E39: https://scholar.google.com/citations?hl=en&user=-FTcY0gAAAAJ
A40: Noel Waclet Cabfilan | C40: 3 | D40: 0 | E40: https://scholar.google.com/citations?hl=en&user=eRYjj_cAAAAJ
...

Sheet Data_2025
A1: No. | B1: Year | C1: College/Institute | D1: Title | E1: Author(s) | F1: Pub Type | G1: Journal/Book | H1: Category | I1: Keywords | J1: URL | K1: Citations | L1: Remarks
A2: 1 | B2: Jan to June 2025 | C2: CPAG/OSS | D2: Meanings and Experiences of Survival Among Filipino Women Survivors of Abuse | E2: Carolyn Busongan Gano and Angeli Tuzon Austria | F2: Journal | G2: Pertanika Journal Social Sciences and Humanities | H2: Peer-reviewed | I2: Coping strategies, Filipino women, the journey of survival, the meaning of survival, women empowerment, women survivors of abuse | J2: https://doi.org/10.47836/pjssh.33.1.03
A3: 2 | B3: Jan to June 2025 | C3: CA | D3: On-Farm Evaluation of Auxin-Treated Sugarcane Bud Chip for Enhanced Growth and Yield | E3: Darwin M Cacal, Janet P Pablo, Darwin A Basquial, Esther Josephine D Sagalla and Leila Mary A Ayban | F3: Journal | G3: Journal of Agriculture and Forest Meteorology Studies | H3: Peer-reviewed | I3: Sugarcane, Budchip, Auxin, Internodes, Bagasse yield | J3: https://manuscriptscientific.com/images/cafe8f883907979ef4cb2f2d57ea9890.pdf | L3: Co-authors
A4: 3 | B4: Jan to June 2025 | C4: CNS | D4: Water quality of Balili River before, during and after COVID: lessons learned and ways forwards for tropical river remediation | E4: Fernie D. SitSit, Romeo M. Dizon & Jones T. Napaldet | F4: Journal | G4: Aquatic Ecology | H4: Scopus/Web of Science | I4: Self-purification, COVID, Water quality, Water quality index, Balili River | J4: https://doi.org/10.1007/s10452-024-10151-0
A5: 4 | B5: Jan to June 2025 | C5: CNAS | D5: Engineering Students’ Expectations about Calculus-based Physics | E5: Thrysha B. Dolipas & Bretel B. Dolipas | F5: Journal | G5: International Journal of Multidisciplinary Educational Research and Innovation 3 (1):284-297 | H5: peer-reviewed | I5: Physics expectations, calculus- based, Physics, sex, senior high school, strand completed | J5: https://philpapers.org/rec/DOLESE
A6: 5 | B6: Jan to June 2025 | C6: CAH | D6: Assessment of Kankanaey Language Resources: A Document Review | E6: Ronda Bataclao Tullay, John Rey Osben Pelila | F6: Journal | G6: Pakistan Journal of Life and Social Sciences | H6: Scopus | I6: Language Assessment, Multilingual Education, Philippines | J6: https://doi.org/10.57239/PJLSS-2025-23.1.00497
A7: 6 | B7: Jan to June 2025 | C7: CNAS | D7: Graduate’s Personal and Professional Impact Assessment: A Degree Program Sustainability Criteria | E7: Bretel B. Dolipas | Maria Azucena B. Lubrica | Serano L. Oryan | Freda Kate D. Samuel | Precious M. Valentin | Joel V. Lubrica | Julie A. Buasen | Phil S. Ocampo | F7: Journal | G7: Journal of Interdisciplinary Perspectives | H7: Peer-reviewed but monthly released with 65 articles per volume | J7: https://www.ejournals.ph/article.php?id=26115
A8: 7 | B8: Jan to June 2025 | C8: CAH | D8: How is English as a Lingua Franca (ELF) Transforming Education in ASEAN Universities? | E8: Mary Faye Suoc, Joanna Lastino, Judilyne Lukingan, Mark Rendel Baraoil, John Rey Pelila | F8: Journal | G8: Journal of Multidisciplinary Research and Development, 2(1), 102–115. | H8: peer-reviewed | I8: stematic literature review, English proficiency, higher education institutions, lingua franca, ASEAN | J8: https://doi.org/10.56916/jmrd.v2i1.1024
A9: 8 | B9: Jan to June 2025 | C9: CPAG | D9: Empirical evidence on the practice of latitude of discretion in personnel selection: Basis for an informed intervention | E9: Renebeth G. Donguiz1*, Narda A. Garcia | F9: Journal | G9: HO CHI MINH CITY OPEN UNIVERSITY JOURNAL OF SCIENCE | H9: peer-reviewed | I9: civil service; governance; human resource; latitude of discretion; merit selection | J9: https://journalofscience.ou.edu.vn/index.php/soci-en/article/view/3553/2329
A10: 9 | B10: Jan to June 2025 | C10: CA | D10: Productivity of corn (Zea mays) under varying drought duration and nitrogen application at La, Trinidad, Benguet | E10: J.P. Pablo G.M. Awidan D.M. Cacal | F10: Journal | G10: Asian Journal of Agriculture and Rural Development Volume 15, Issue 1 (2025): 30-38 | H10: Scopus | I10: Corn, Drought, Nitrogen, Productivity, Vegetative, Water stress, Zea mays | J10: https://archive.aessweb.com/index.php/5005/article/view/5299/8167
A11: 10 | B11: Jan to June 2025 | C11: CPAG | D11: Home-Based Community Internship Model: Exploring Employment Outcomes and Educational Strategies in Public Administration in Benguet, Philippines | E11: Atty. Julie M. Binaldo-Velasco | F11: Journal | G11: Pedagogy Review: An International Journal of Educational Theories, Approaches and Strategies 2025, Vol. 4, No.2, 214 – 228 | | H11: peer-reviewed | I11: home-based internship, employment outcomes, educational strategies, public administration | J11: https://doi.org/10.62718/vmca.pr-ijetas.4.2.SC-0225-021
A12: 11 | B12: Jan to June 2025 | C12: CAH | D12: Assessing archaism in Philippine Indigenous languages: the case of Kankanaey as spoken in Mankayan, Benguet, Philippines | E12: John Rey Osben Pelila, Shirley Lacson Ayao-ao | F12: Journal | G12: AlterNative: An International Journal of Indigenous Peoples Volume 21, Issue 1 Pages: 54 - 63 | H12: Web of Science | I12: archaism Indigenous people language assessment mixed-method design Philippines | J12: https://doi.org/10.1177/11771801241309727
A13: 12 | B13: Jan to June 2025 | C13: CAH | D13: How Do Schools and Community Influence Indigenous Youth's Perceptions of English? | E13: Liaa Eve Dalilis Tacio, John Rey Osben Pelila | F13: Journal | G13: Indonesian Journal of Research and Educational Review Volume 4, No. 2, 2025, pp 263 - 274 | H13: peer-reviewed | I13: English as a dominant language, Indigenous youth, Language, Phenomenological research, Philippines | J13: https://doi.org/10.51574/ijrer.v4i2.2851
A14: 13 | B14: Jan to June 2025 | C14: CE | D14: Development of a multi-commodity hammer mill for smallscale milling operation | E14: E N Dominguez*, C P Basquial | F14: Journal | G14: IOP Conf. Series: Earth and Environmental Science 1477 (2025) 012051 | H14: Scopus | J14: 10.1088/1755-1315/1477/1/012051
A15: 14 | B15: Jan to June 2025 | C15: CAH | D15: Semantics of Cardinal Directions in Benguet Cultural Practices | E15: John Rey Pelila, Von Ameri Escobar, Jessa Mariel Pilorin, Geraldine Wakat | F15: Journal | G15: Scholar: Human Sciences, 17(1), 317-327. | H15: peer-reviewed | I15: Linguistics, Culture, Meaning, Language Education, Philippines | J15: https://doi.org/10.14456/shserj.2025.30
A16: 15 | B16: Jan to June 2025 | C16: CHK | D16: Bridging gaps, wearable tech, apps and physical activity in older adults | E16: Charvet Caytap | F16: Journal | G16: Scientific Journal of Sport and Performance, 4(4), 470–479. | H16: peer-reviewed | I16: PrEAP model, Wearable trackers, Smart phone apps, Technology adoption, Healthcare, Aging | J16: https://doi.org/10.55860/WXFV1725
A17: 16 | B17: Jan to June 2025 | C17: CNS | D17: Assessment of conservation benefits of ecotourism in secondary forest ecosystems using PD-ZTCM-WTP in Mt Yangbew, Benguet, Philippines | E17: Allen Rey S. POTINGAN, Collen C. COIS, Remo M. BASILIO, Jones T. NAPALDET | F17: Journal | G17: Taiwania 70(1): 156‒170 | H17: Scopus/Web of Science | I17: plant diversity, quantification of ecotourism benefits, Benguet, Zone Travel Cost Method, willingness to pay | J17: https://www.researchgate.net/profile/Jones-Napaldet/publication/389008974_Assessment_of_conservation_benefits_of_ecotourism_in_secondary_forest_ecosystems_using_PD-ZTCM-WTP_in_Mt_Yangbew_Benguet_Philippines/links/67b00585461fb56424db8398/Assessment-of-conservation-benefits-of-ecotourism-in-secondary-forest-ecosystems-using-PD-ZTCM-WTP-in-Mt-Yangbew-Benguet-Philippines.pdf
A18: 17 | B18: Jan to June 2025 | C18: BSU-Buguias | D18: The Influence of Online Learning on the Academic and Social Behaviors of College Students | E18: Gleemoore C. Makie, Mary Ruth V. Datario, Jocelda Nova C. Vidal | F18: Journal | G18: Journal of Interdisciplinary Perspectives | H18: Peer-reviewed but monthly released with 65 articles per volume | I18: Online learning; College students; Academic behavior, Social behavior | J18: https://www.researchgate.net/profile/Gleemoore-Makie/publication/390920397_The_influence_of_online_learning_on_the_academic_and_social_behaviors_of_college_students/links/68025810d1054b0207d5152f/The-Influence-of-Online-Learning-on-the-Academic-and-Social-Behaviors-of-College-Students.pdf
A19: 18 | B19: Jan to June 2025 | C19: CA | D19: Advancements in Chemiresistive and Electrochemical Sensing Materials for Detecting Volatile Organic Compounds in Potato and Tomato Plants | E19: Baba, T.; Janairo, L.G.; Maging, Novelyn.; Tañedo, H.S.; Concepcion, R., II; Magdaong, J.J.; Bantang, J.P.; Del-amen, J.; Culaba, A. | F19: Journal | G19: AgriEngineering 2025, 7, 166. | H19: Scopus/Web of Science | I19: polymer sensor; hybrid material; precision agriculture; sustainable agriculture; volatile organic compounds; wearable sensor | J19: https://doi.org/10.3390/agriengineering7060166
A20: 19 | B20: Jan to June 2025 | C20: CHK | D20: Rapid weight loss in combative sports | E20: Karn Jariya M. Amado | F20: Journal | G20: Scientific Journal of Sport and Performance, 4(3), 466–469. | H20: peer-reviewed | I20: RWL, Athletes, Sport medicine, Psychological effect, Physical activity psychology | J20: https://doi.org/10.55860/CTMQ9059
A21: 20 | B21: Jan to June 2025 | C21: CA | D21: Phenotypic Characterization and Correlation Analysis in Quinoa (Chenopodium quinoa Willd.) Entries Cultivated in Itogon and La Trinidad, Benguet | E21: Flori Joyce D. Cariño and Esther Josephine D. Sagalla | F21: Journal | G21: Mountain Journal of Science and Interdisciplinary Research vol. 85 no.1 | H21: Scopus | I21: Chenopodium quinoa, correlation Analysis, phenotypic characterization | J21: http://portal.bsu.edu.ph:8083/index.php/BRJ/article/view/459
A22: 14 | B22: Jan to June 2025
A23: 15 | B23: Jan to June 2025
A24: 16
A25: 17
A26: 18
A27: 19
A28: 20
A29: 21
A30: 22
A31: 23
A32: 24
A33: 25
A34: 26
A35: 27
... A61: 53
A62: 21 | B62: Jan to June 2025 | C62: CNAS | D62: Geographical Variation, Path Diagram, and Regression Tree of the Incidence and Severity of Potato Late Blight (Phytophthora infestans): The Obesrved Pattern in the Major Growing Areas in Benguet Province | E62: Han B. Bonoy and Precious M. Valentin | F62: Journal | G62: Mountain Journal of Science and Interdisciplinary Research vol. 85 no.1 | H62: Scopus | I62: Cluster analysis, path analysis, Cart model, disease tetrahedron, potato late blight | J62: http://portal.bsu.edu.ph:8083/index.php/BRJ/article/view/458
A63: 22 | B63: Jan to June 2025 | C63: NPRCRTC | D63: Impacts of Technology Interventions on Managing Fusarium Wilt in Sweetpotato in Bauko, Mountain Province | E63: Dalen T. Meldoz, Teresita S. Masangcay, Cynthia G. Kiswa, and Analiza V. Alzarate | F63: Journal | G63: Mountain Journal of Science and Interdisciplinary Research vol. 85 no.1 | H63: Scopus | I63: sweetpotato, tissue culture-derived plant, material, fusarium wilt | J63: http://portal.bsu.edu.ph:8083/index.php/BRJ/article/view/462
A64: 23 | B64: Jan to June 2025 | C64: HORTI/CA | D64: Fresh Pod Yield and Stability of NSIC-Approved Varieties of Pole Snap Bean (Phaseolus vulgaris (L.)) in Benguet | E64: Margie E. Bad-ey, Leoncia L. Tandang, Hector C. Gayomba, and Johnson G. Bagtila | F64: Journal | G64: Mountain Journal of Science and Interdisciplinary Research vol. 85 no.1 | H64: Scopus | I64: Pole Sap Bean, On-Farm Trial, Fresh Pod Yield, GxE Interaction, Stability | J64: https://doi.org/10.70884/mjsir.v85i1.456
A65: 24 | B65: Jan to June 2025 | C65: CVM | D65: Hygiene Knowledge,Attitudes, and Practices (KAP) of Retailers and their Association to E.coli Contamination in pork Sold in La Trinidad, Benguet | E65: Edlyn Mae N. Ciano | F65: Journal | G65: Mountain Journal of Science and Interdisciplinary Research vol. 85 no.1 | H65: Scopus | I65: KAP (Knowledge, Attitudes, and Practices), E. coli contamination, pork | J65: http://portal.bsu.edu.ph:8083/index.php/BRJ/article/view/457
...

Sheet Data_2024
A1: No. | B1: Year | C1: College/Institute | D1: Title | E1: Author(s) | F1: Pub Type | G1: Journal/Book | H1: Category | I1: Keywords | J1: URL | K1: Citations | L1: Remarks
A2: 1 | B2: Jan to June 2024 | C2: CAH | D2: Message patterns through discourse analysis on the concept of apology and forgiveness during Ramadan among college students practicing Islam | E2: Jason V. Chavez, Jhordan T. Cuilan, Haydee G. Adalia | F2: Journal | G2: Environment and Social Psychology | H2: Scopus 2019 to present | I2: communication; apologizing; forgiveness; Islamic beliefs; Ramadan | J2: https://esp.apacsci.com/index.php/esp/article/view/2043 | K2: https://scholar.google.com/citations?view_op=view_citation&hl=en&user=Y5Ot_3wAAAAJ&citation_for_view=Y5Ot_3wAAAAJ:IjCSPb-OGe4C
A3: 2 | B3: Jan to June 2024 | C3: CAH | D3: Gender mainstreaming campaign as a casualty of the online gender-based humor: A discourse analysis | E3: Jason V. Chavez, Jhordan T. Cuilan | F3: Journal | G3: Environment and Social Psychology | H3: Scopus 2019 to present | I3: cultivation; discourse markers; gender-based humor; gender mainstreaming; message patterns; social media | J3: https://esp.apacsci.com/index.php/esp/article/view/2044 | K3: https://scholar.google.com/citations?view_op=view_citation&hl=en&user=Y5Ot_3wAAAAJ&citation_for_view=Y5Ot_3wAAAAJ:UeHWp8X0CEIC
A4: 3 | B4: Jan to June 2024 | C4: CHET/FSRIC | D4: Phenolic-rich lees from Philippine rice wine (tapuy) increases Caenorhabditis elegans lifespan in spite of having low antioxidant activity | E4: Sean Philippe L. Chua, Lesley Dale Umayat & Paul Mark B. Medina | F4: Journal | G4: Food Production, Processing and Nutrition 6:1, 1-12. | H4: Scopus 2019 to present; Clarivate (Emerging Sources Citation Index) | I4: Rice wine, Tapuy, Lees Lifespan, Caenorhabditis elegans, Fermented food | J4: https://doi.org/10.1186/s43014-023-00181-w | K4: https://scholar.google.com/citations?view_op=view_citation&hl=en&user=dVCbH7cAAAAJ&cstart=20&pagesize=80&citation_for_view=dVCbH7cAAAAJ:epqYDVWIO7EC
A5: 4 | B5: Jan to June 2024 | C5: CTE | D5: Pathways to a Succesful Career: Unveiling the PostGraduate Journey – A Tracer Study | E5: Imelda G Parcasio, Russell B Dolendo, Brenda A Langaoen, Percyveranda A Lubrica | F5: Journal | G5: Social Sciences, Humanities and Education Journal | H5: Open Access Peer-reviewed | I5: Educational Management, Employment, Professional Growth, Curricular Activities | J5: http://doi.org/10.25273/she.v5i1.19223 | K5: https://scholar.google.com/citations?view_op=view_citation&hl=en&user=WHPuq_QAAAAJ&citation_for_view=WHPuq_QAAAAJ:Y0pCki6q_DkC
A6: 5 | B6: Jan to June 2024 | C6: CF | D6: Impacts of the COVID-19 Pandemic on Livelihood Assets of Smallholder Agroforestry Farmers in Selected Upland Farming Communities in the Philippines | E6: Leila Landicho, Kenneth A. Laruan, Mary Anne G. Abadillos and Romnick S. Pascua | F6: Journal | G6: Forest and Society, Vol. 8 No. 1 | H6: Scopus 2017 to present; Clarivate (ESCI) | I6: Smallholder, COVID-19, Pandemic, Agroforestry, Philippines | J6: https://doi.org/10.24259/fs.v8i1.28095 | K6: https://scholar.google.com/citations?view_op=view_citation&hl=en&user=PyO6wrQAAAAJ&citation_for_view=PyO6wrQAAAAJ:Y0pCki6q_DkC
A7: 6 | B7: Jan to June 2024 | C7: CF | D7: Generating Wall-to-Wall Canopy Height Information from Discrete Data Provided by Spaceborne LiDAR System | E7: Nova D. Doyog, Chinsu Lin | F7: Journal | G7: Forest Volume 15 No. 3, 482 | H7: Scopus 2010 to Present; Clarivate (Science Citation Index Expanded) | I7: integrated RS- and ML-based canopy height modeling; GEDI; ICESat-2; SAR; challenges in canopy height modeling | J7: https://doi.org/10.3390/f15030482 | K7: https://scholar.google.com/citations?view_op=view_citation&hl=en&user=-WSRHRgAAAAJ&citation_for_view=-WSRHRgAAAAJ:UebtZRa9Y70C
A8: 7 | B8: Jan to June 2024 | C8: ULIS | D8: Information Sources Preferred by Students in Academic Writing | E8: Noel W. Cabfilan | F8: Journal | G8: DESIDOC Journal of Library & Information Technology, Vol. 44, No. 1, | H8: Scopus from 2012 to Present; Clarivate (Emerging Sources Citation Index) | I8: Information sources; Library resources; Online resources; Print resources | J8: https://doi.org/10.14429/djlit.44.1.18909 | K8: https://scholar.google.com/citations?view_op=view_citation&hl=en&user=eRYjj_cAAAAJ&citation_for_view=eRYjj_cAAAAJ:2osOgNQ5qMEC
A9: 8 | B9: Jan to June 2024 | C9: CNS | D9: Development of endemicity and conservation importance indices for tropical forests and the floral diversity assessment of Mt. Natoo in Benguet, Philippines | E9: Johndale Rein T. Bullong, Jim P. Silverio, Joanna I. Alafag, Maricel A. Guron & Jones T. Napaldet | F9: Journal | G9: Journal of Mountain Science Volume 21, pages 428–446 | H9: Scopus from 2007 to Present/Clarivate (SCIE) | I9: Endemicity index, Conservation importance index, Cordillera Central Range, Floristic element, Jaccard Index of Similarity, | J9: https://doi.org/10.1007/s11629-023-8387-9 | K9: https://scholar.google.com/citations?view_op=view_citation&hl=en&user=SCSvSk0AAAAJ&citation_for_view=SCSvSk0AAAAJ:2osOgNQ5qMEC
A10: 9 | B10: Jan to June 2024 | C10: CNS | D10: Application of microorganisms for cross-protection against biotic and metal-induced oxidative stresses in plants | E10: Sherlyn C. Tipayno | F10: Chapter in a Book | G10: Beneficial Microbes for Sustainable Agriculture Under Stress Conditions Functional Traits and Regulation 2024, Pages 201-213 | J10: https://doi.org/10.1016/B978-0-443-13193-6.00011-7 | K10: https://scholar.google.com/citations?view_op=view_citation&hl=en&user=mRtnrlsAAAAJ&citation_for_view=mRtnrlsAAAAJ:7PzlFSSx8tAC
A11: 9 | B11: Jan to June 2024 | C11: CAH | D11: Investigating The Relationship Between Leadership, Self-Efficacy, And Research Productivity In Educational Settings | E11: Fahad A. Salendab, Peter B. Rama Jr, Robert F. Galindez, Dr. Cinder Dianne L. Tabiolo, Norman P. Romasanta, Adamson N. Labi, Leonilo B. Capulso | F11: Journal | G11: Migration Letters Volume: 21, No: S3 (2024), pp. 856-873 | H11: Open access peer-reviewed Scopus from 2011 to 2022 (coverage discontinued in Scopus) not in Clarivate database | I11: Leadership characteristics, Research self-efficacy, Research productivity, Educational settings, Philippines | J11: https://migrationletters.com/index.php/ml/article/view/6869/4558
A12: 11 | B12: Jan to June 2024 | C12: BSU-Buguias | D12: LEADERSHIP STYLE PREFERENCES OF BSU-BUGUIAS CAMPUS FACULTY AND STAFF | E12: Elizabeth M. Bay-an, Jayne B. Miranda, Princess Irene B. Patacsil, Lemar A. Ablasa | F12: Journal | G12: Ignatian International Journal for Multidisciplinary Research Vol 2 No 3 | H12: Open Access Peer-reviewed | I12: leadership style, preferences, Laissez-faire, Democratic, Transactional | J12: https://doi.org/10.5281/zenodo.10890234
A13: 12 | B13: Jan to June 2024 | C13: BSU-Buguias | D13: COPING MECHANISMS IN THE NEW MODALITIES OF TEACHING IN PUBLIC ELEMENTARY SCHOOLS | E13: Lemar A. Ablasa and Genevieve N. Olban | F13: Journal | G13: Ignatian International Journal for Multidisciplinary Research Vol 2 No 2 | H13: Open Access Peer-reviewed | I13: Innovation, platforms, mutual learning, standard hygiene, cognitive appraisal, challenges, stressful job | J13: https://doi.org/10.5281/zenodo.10701774
A14: 13 | B14: Jan to June 2024 | C14: BSU-Buguias | D14: EFFECTIVE APPROACHES EMPLOYED BY ELEMENTARY TEACHERS IN CHRISTIAN SCHOOLS | E14: Lemar A. Ablasa, Janice O. Bagano | F14: Journal | G14: Ignatian International Journal for Multidisciplinary Research Vol 2 No 2 | H14: Open Access Peer-reviewed | I14: Best practices, strategies, differentiated instruction, factors, controllable, physical stamina | J14: https://doi.org/10.5281/zenodo.10719955
A15: 14 | B15: Jan to June 2024 | C15: BSU-Buguias | D15: PARENTS LIVED EXPERIENCES AS STUDY BUDDY OF LEARNERS IN THE NEW NORMAL | E15: Lemar A. Ablasa, Janice K. Bagano and Flordeliza D. De Guzman | F15: Journal | G15: Ignatian International Journal for Multidisciplinary Research Vol 2 No 3 | H15: Open Access Peer-reviewed | I15: COVID-19 pandemic, parental skills, guiding time learning moments, study buddy, roles, formal education | J15: https://doi.org/10.5281/zenodo.10781887
A16: 15 | B16: Jan to June 2024 | C16: BSU-Bokod | D16: Dissemination of the Vision, Mission, Goals, and Objectives of Urdaneta City University: Ethical Implications to Integrity, Teamwork, Competence and Transcendence | E16: Gleemoore C. Makie | F16: Journal | G16: International Journal Of Empirical Research Methods Volume 2, Issue 1, PP: 53-71 | H16: Open Access Peer-reviewed | I16: Extent, Dissemination, Vision, Mission, Goal, Objectives | J16: https://www.guinnesspress.org/assets/articles/pdf/ijerm-v2-5-52471-Gleemoore-C.-Makie.pdf
A17: 10 | B17: Jan to June 2024 | C17: CAH | D17: A SCOPING REVIEW OF LANGUAGE PROGRAMS AND POLICIES IN ASEAN COUNTRIES | E17: Alexee Jaezhelle C. Pugong, John Rey Osben Pelila, Matin Evony P. Moling, Jocel T. Dolo, Norhana A. Usman | F17: Journal | G17: Indonesian Journal of Research and Educational Review Volume 3, No. 2, 2024, pp 82-102 | H17: Open Access Peer-reviewed | I17: ASEAN Countries; Languge; Programs and Policies; Scoping Review | J17: https://doi.org/10.51574/ijrer.v3i2.1181 | K17: https://scholar.google.com/citations?view_op=view_citation&hl=en&user=mi5aC-4AAAAJ&citation_for_view=mi5aC-4AAAAJ:W7OEmFMy1HYC
A18: 11 | B18: Jan to June 2024 | C18: CE | D18: Impact of using glucose as a sole carbon source to analyze the effect of biochar on the kinetics of biomethane production | E18: Valentin, M.T., Białowiec, A | F18: Journal | G18: Scientific Reports | H18: Clarivate (Web of Science -SCIE); Scopus from 2011 to present | I18: Biochar, Glucose, Kinetics, Digestion, Biomethane | J18: https://doi.org/10.1038/s41598-024-59313-y | K18: https://scholar.google.com/citations?view_op=view_citation&hl=en&user=8_fUSUcAAAAJ&citation_for_view=8_fUSUcAAAAJ:0EnyYjriUFMC
A19: 12 | B19: Jan to June 2024 | C19: BSU-Bokod | D19: Poetic Justice, Love, and Womanhood | E19: Gleemore Makie, Christopher Ryan Maboloc | F19: Journal | G19: Social Ethics Society Journal of Applied Philosophy Special Issue, February 2024, 280-291 | H19: Open Access Peer-reviewed | I19: Radicalism; Rodrigo Duterte; Poetry, Ideal Love; Women | J19: https://ses-journal.com/wp-content/uploads/2024/03/SES-Journal_Special-Issue_Feb-2024_Article-13_final-1.pdf | K19: https://scholar.google.com/citations?view_op=view_citation&hl=en&user=GaRs-FgAAAAJ&cstart=20&pagesize=80&citation_for_view=GaRs-FgAAAAJ:uWQEDVKXjbEC
A20: 13 | B20: Jan to June 2024 | C20: CAH | D20: Pinoylish: The Awareness and Notions of University Students in Northern Luzon | E20: Joseph B. Quinto | F20: Journal | G20: TEFLIN Journal, Volume 35, Number 1, 2024 | H20: ASEAN Citation Index but articles uploaded until 2022 only Scopus from 2018 to 2023 only | I20: English language teaching, Philippine English, Pinoylish, pluricentric model | J20: http://dx.doi.org/10.15639/teflinjournal.v35i1/107-122 | K20: https://scholar.google.com/citations?view_op=view_citation&hl=en&user=hTEK3WYAAAAJ&citation_for_view=hTEK3WYAAAAJ:Se3iqnhoufwC
A21: 14 | B21: Jan to June 2024 | C21: CTE/HERRC | D21: Alumni’s Retrospective Evaluation of their Undergraduate Secondary Teacher Education Training | E21: Apler J. Bansiong and Dolores Alawas | F21: Journal | G21: Mountain Journal of Science and Interdiciplinary Research | H21: Scopus | I21: 21st-century skills, Alumni feedback, Retrospective evaluation by alumni, Graduate tracer study, curriculum, Physical resources | J21: http://portal.bsu.edu.ph:8083/index.php/BRJ/article/view/400/418 | K21: https://scholar.google.com/citations?view_op=view_citation&hl=en&user=Y3vamKYAAAAJ&citation_for_view=Y3vamKYAAAAJ:LkGwnXOMwfcC
A22: 15 | B22: Jan to June 2024 | C22: IFHSA | D22: Fungal Contaminants and Cup Quality of Stored Roasted Arabica Coffee | E22: Von Y. Amado, Andres A. Basalong, And Hazen Lyn B. Talbino | F22: Journal | G22: Mountain Journal of Science and Interdiciplinary Research | H22: Scopus | I22: Arabica coffee, storage, microbial contamination, cup quality | J22: http://portal.bsu.edu.ph:8083/index.php/BRJ/article/view/397/415
A23: 16 | B23: Jan to June 2024 | C23: CAH | D23: The Use of Podcasts for Language Learning: A Systematic Review of Literature | E23: Michaela G. Ramirez | F23: Journal | G23: International Journal of English Language Studies | H23: Scopus | I23: Podcasts, language, learning, benefits, drawbacks, roles of podcast, systematic review | J23: https://doi.org/10.32996/ijels.2024.6.1.4
A24: 17 | B24: Jan to June 2024 | C24: CA | D24: Verification on Energy Digestibility in Ground Yellow Corn, Rice Bran, and Copra Expeller Fed to 10 to 15 kg Benguet Native Pigs | E24: Mineralito F. Simon and Mary Arnel D. Garcia | F24: Journal | G24: Mountain Journal of Science and Interdiciplinary Research | H24: Scopus | I24: digestibility trial, feeding standard, indigenous pig, nutrition, feed ingredients | J24: http://portal.bsu.edu.ph:8083/index.php/BRJ/article/view/398/416
A25: 18 | B25: July to December 2024 | C25: CF | D25: Cultural and Spiritual Adaptations to Extreme Weather Events of Ethnic Farming Communities of the Three Watersheds Situated at Different Altitudinal Locations along Agno River Basin, Benguet and Pangasinan, Philippines | E25: Josel M. Florentin and Emerson V. Barcellano | F25: Journal | G25: Vol. 2 No. 4 (2024): European Journal of Theoretical and Applied Sciences | H25: Open access peer-reviewed | I25: Agno River Basin, Ethnic farming communities, Cultural/spiritual adaptations, extreme weather, climate- related hazards | J25: https://doi.org/10.59324/ejtas.2024.2(4).14
A26: 19 | B26: July to December 2024 | C26: CNS | D26: Ecological insights on communal forests in the tropics: The case of Alapang Communal Forest of La Trinidad, Benguet, Philippines | E26: Marvin P. POCYOY, Jones T. NAPALDET | F26: Journal | G26: Taiwania | H26: SCOPUS/ Clarivate/ Web of Science (ISI) | I26: carbon stock, community perspective, depressed station, Pinus kesiya, urban communal forest. | J26: https://www.researchgate.net/profile/Jones-Napaldet/publication/382889888_Ecological_insights_on_communal_forests_in_the_tropics_The_case_of_Alapang_Communal_Forest_of_La_Trinidad_Benguet_Philippines/links/66b21fdd51aa0775f26d7ef5/Ecological-insights-on-communal-forests-in-the-tropics-The-case-of-Alapang-Communal-Forest-of-La-Trinidad-Benguet-Philippines.pdf
A27: 20 | B27: July to December 2024 | C27: CF | D27: Indigenous Ecological Knowledge and Systems of Ethnic Farmers Located at Different Altitudinal Locations along Agno River, Philippines | E27: Josel M. Florentin and Emerson V. Barcellano | F27: Journal | G27: American Journal of Agricultural Science, Engineering, and Technology | H27: Open access peer-reviewed | I27: Climate Stressors, Ethnic Communities, Farming Techniques, Indigenous Knowledge and Systems, Watershed | J27: https://doi.org/10.54536/ajaset.v8i3.3347
A28: 21 | B28: July to December 2024 | C28: CNS | D28: Self-purification in tropical upland rivers as affected by environmental factors: the case of Balili River in Benguet, Philippines | E28: Mercedes K. Ago,Regine D. Caasi,Divina S. Kege-e &Jones T. Napaldet | F28: Journal | G28: International Journal of Phytoremediation | H28: Scopus 1994, from 1996 to 2024, WoS (Science Citation Index Expanded) | I28: Canonical correspondence analysis, elevation, floral diversity, natural regeneration | J28: https://doi.org/10.1080/15226514.2024.2380751
A29: 22 | B29: Jan to June 2024 | C29: CIS | D29: 8-Week Self-Training Program in Sepak Takraw | E29: Dustin Paolo Tinte Cruz, Russell B. Dolendo | F29: Journal | G29: Puissant | H29: Open access peer-reviewed | I29: quasi-experimental, physical fitness, training program, athletes, performances | J29: https://www.puissant.stepacademic.net/puissant/article/view/403
A30: 23 | B30: July to December 2024 | C30: CA | D30: Genetic diversity and population structure of Philippine strawberry germplasm based on genome-wide simple sequence repeat markers | E30: Elec VH, Cadorna CAE, Tad-Awan BA, Basquial DA, Dumaslan MR, Rey JD | F30: Journal | G30: Biodiversitas | H30: Clarivate (Zoological records)/Scopus from 2014 to present/ACI | I30: dmixture, genetic diversity, geographic origin, Philippine strawberry, SSRs | J30: https://smujo.id/biodiv/article/view/17437
A31: 24 | B31: Jan to June 2024 | C31: CHET | D31: PO-MU-MA Emergency food bar: nutritional, microbial, sensorial, and cost analysis | E31: Lyka Mae Socao Ibayan Frenzel May Diano Bauding Maxyne Piper Salupen Cabading Bernadette Manuel Cayabyab Pelin Bugtong Belino | F31: Journal | G31: Brazilian Journal of Development | H31: Open access peer-reviewed | I31: emergency food bar, potato, mung bean, malunggay | J31: https://doi.org/10.34117/bjdv10n6-065
A32: 25 | B32: July to December 2024 | C32: CPAG | D32: From Social Media Engagement to Voting Decisions: Influence of Social Media on Local Election | E32: John Wilson C. Nicolas; Renebeth G. Donguiz | F32: Journal | G32: Cognizance Journal of Multidisciplinary Studies | H32: Open access peer-reviewed | I32: Social media engagement, voting behavior, voting decisions, voter turnout | J32: https://d1wqtxts1xzle7.cloudfront.net/117047837/V4I705-libre.pdf?1722010120=&response-content-disposition=inline%3B+filename%3DFrom_Social_Media_Engagement_to_Voting_D.pdf&Expires=1728614860&Signature=gJciSO6jNJGkz3hrJIvoUiRjdY2t5A05Il5dlRTLSEjPnLtlX7xnX-p4fMrbBeWstBQR3fRWcUV6BWjw62f8N8w~ZYIqlCQiJdiQRYkScygVGQkuerVGugG9p~wVYX-SKVaROzFPoAWpGTUz7q-KnofEYHhwDQJHp48tzY8tsrsm04~C-MCh9tqfm5IAgRRJvT4PkCtMMfFmSNUoYn76tJF7qncEHhJXOA3oX1hfrmz6FtPKH9YXgI2vfYtgXnPChbrY~2Jzxrg~XjQoEkQJlEc2C4LHqll-8MTzYnsc-Xg8VmF6QWQiELizOmS~z67LdOvFUPlPPkTg4FiT7iK1MQ__&Key-Pair-Id=APKAJLOHF5GGSLRBV4ZA
A33: 26 | B33: July to December 2024 | C33: CAH | D33: Self-efficacy in communication and employability skills of English language students | E33: Joerene Mae Layagan | F33: Journal | G33: ELT Forum: Journal of English Language Teaching | H33: Open access peer-reviewed | I33: employability, English language students, employable skills, written communication skills, oral communication skills | J33: https://doi.org/10.15294/elt.v13i2.1516
... A35: 28 | B35: July to December 2024 | C35: CAH | D35: Internship Experience: The MMMAPS, the WorST, and the Interns | E35: Joseph B. Quinto, Frances Mae G. Diase | F35: Journal | G35: Informasi | H35: Open access peer-reviewed | I35: career trajectories, hurdles, internship experience, CMO number 35, series of 2017 | J35: https://scholarhub.uny.ac.id/informasi/vol54/iss1/1/
A36: 29 | B36: Jan to June 2024 | D36: Methods Used in YouTube for Teaching and Learning English Language: A Systematic Literature Review | E36: Rufino, Gilliane G. | F36: Journal | G36: International Journal of English Language Studies, 6(1), 82–97. | H36: Scopus from 2019 to 2024 | I36: YouTube, English Learning, Audio-Visual | J36: https://doi.org/10.32996/ijels.2024.6.1.9%20
A37: 30 | B37: July to December 2024 | C37: CAH | D37: Pragmatic Instructions in Oral Communication in Context | E37: Joseph B Quinto | F37: Journal | G37: JLE: Journal of Literate of English Education Study Program, 5(1), 1-16. | H37: Open access peer-reviewed | I37: interlanguage pragmatics, oral communication in context, pragmatic instructions | J37: https://doi.org/10.47435/jle.v5i1.2952
A38: 31 | B38: July to December 2024 | C38: CAH | D38: The Dichotomy of Thumbs-Up Emoji in Online Conversations | E38: John Rey Osben Pelila, Jayson Ace Kigis Abenoja, Troy Pangwi Raymundo | F38: Journal | G38: INDONESIAN JOURNAL OF EDUCATIONAL RESEARCH AND REVIEW Volume 7 Nomor 2 2024, pp 347-356 | H38: Open access peer-reviewed | I38: Emoji, Komunikasi Online, Tinjauan Literatur Sistematis | J38: https://doi.org/10.23887/ijerr.v7i2.75698
A39: 32 | B39: Jan to June 2024 | C39: CPAG | D39: Application Of The Levinisian Face-To-Face Dialogue Among Local Government Units: Basis Of Trendsetting Organizational Communication | E39: Renebeth Gatudan Donguiz | F39: Journal | G39: Cultural Landscape Insights | H39: Open access peer-reviewed | I39: Organizational Communication Levinas Face-To-Face Dialogue Organizational Change | J39: https://doi.org/10.59762/cli901324532120240305153643
A40: 33 | B40: July to December 2024 | C40: ULIS | D40: A Bibliometric Analysis of Benguet State University Research Journals (1977–2023): Implications for Library Resource Acquisitions, Access, and Services | E40: Daniel S. Balbin Jr. | F40: Journal | G40: Science & Technology Libraries | H40: Scopus from 1980 to 2008, from 2010 to 2024 | I40: Bibliometric analysislibrary accesslibrary acquisitionperformance analysisresearch productivityscience mapping | J40: https://doi.org/10.1080/0194262X.2024.2434836
A41: 34 | B41: July to December 2024 | C41: CAH | D41: In What Ways Do Educators Respond to Plagiarism Among Students? | E41: John Rey Osben Pelila, Johnell B. Desalit, Bernadette L. Soliba | F41: Journal | G41: Indonesian Journal of Research and Educational Review | H41: Open access peer-reviewed | I41: Higher Education, Philippines, Plagiarism, Output-Based Assessment | J41: https://doi.org/10.51574/ijrer.v3i4.1971
...

Sheet Data_2023
A1: No. | B1: Year | C1: College/Institute | D1: Title | E1: Author(s) | F1: Pub Type | G1: Journal/Book | H1: Category | I1: Keywords | J1: URL | K1: Citations | L1: Remarks
A2: 1 | B2: Jan-June 2023 | C2: CAH | D2: TeachTokerists in the Philippines: A Husserlian Phenomenology | E2: Joseph B. Quinto and Denver M. Cho-oy | F2: Journal | G2: Asia Social Issues | H2: open access peer-reviewed | I2: TikTok, Husserlian phenomenology, TeachTokerists, EduTok, Short-video platform | J2: https://so06.tci-thaijo.org/index.php/asi/article/view/258636/174963
A3: 2 | B3: Jan-June 2023 | C3: CF/GIS | D3: Biomass and Carbon Stock Assessment of Trees in the Lowland Evergreen Forest of Mt. Iraya, Batanes, Philippines | E3: Roscinto Ian C. Lumbres*, Deign Frolley C. Soriano, Nova D. Doyog, Romel A. Raterta, Severino C. Villarta Jr., and Zenaida G. Baoanan | F3: Journal | G3: Philippine Journal of Science | H3: Clarivate (Web of Science - Zoological Records); Scopus from 2009 to present | I3: carbon sequestration, climate change, forest conservation, forest biometry, greenhouse gas, protected area | J3: https://philjournalsci.dost.gov.ph/images/pdf/pjs_pdf/vol152no1/biomass_and_carbon_stock_assessment_of_tress_in_Mt_Iraya_Batanes_.pdf
A4: 3 | B4: Jan-June 2023 | C4: BSU-Bokod | D4: Discourse of culture and ideology in two African novels: Evolving a proto-literacy model | E4: Chester B. Esnara | F4: Journal | G4: Research Journal in Advanced Humanities | H4: Scopus from 2020 to present | I4: Discourse of culture and ideology, proto-literacy model, critical discourse analysis or CDA, processes of transitivity, language-literature interface, African novel | J4: https://royalliteglobal.com/advanced-humanities/article/view/989
A5: 4 | B5: Jan-June 2023 | C5: CE | D5: Investigation of the performance of a cylindrical hopper and metering device of a carrot seeder | E5: Marvin T. Valentin, Andrzej Białowiec, Davut Karayel, Algirdas Jasinskas, Daniel Ciolkosz & Jeffrey A. Lavarias | F5: Journal | G5: Scientific Reports | H5: Clarivate (Web of Science -SCIE); Scopus from 2011 to present | I5: Applied mathematics, Engineering, Mathematics and computing, Mechanical engineering | J5: https://www.nature.com/articles/s41598-022-25798-8
A6: 5 | B6: Jan-June 2023 | C6: CN | D6: Vaccine wastage in the Philippines: An examination of the contributory factors | E6: Gilbert D. Bernardino Jr., Karolyn Rae A. Yogyog, Jude L. Tayaben, Paul Froilan U. Garma | F6: Commentary | G6: Public Health Challenges | H6: Wiley | I6: COVID-19, disinformation, health literacy, public–private partnerships, vaccine hesitancy, vaccinewastage | J6: https://onlinelibrary.wiley.com/doi/epdf/10.1002/puh2.50
A7: 6 | B7: Jan-June 2023 | C7: CF/GIS | D7: Climate risk vulnerability assessment on the production of heirloom rice (Oryza sativa L.) and Arabica coffee (Coffea arabica L.) in Mountain Province, Philippines | E7: Levi Ezekiel O. Daipan, Roscinto Ian C. Lumbres*, Myra Nieves T. Lingaling, Lynn J. Talkasen, Quinerlyn A. Godio, Guillermo A. Mendoza | F7: Journal | G7: SciEnggJ | H7: Clarivate (Web of Science - Zoological Records)/Scopus | I7: Climate risk, vulnerability, heirloom rice, Arabica coffee, exposure, sensitivity, adaptive capacity | J7: https://scienggj.org/2023/SciEnggJ%202023-vol16-no01-p28-39-Daipan%20et%20al.pdf
A8: 7 | B8: Jan-June 2023 | C8: CF | D8: Diversity assessment and listing of birds in Mt. Santo Tomas Forest Reserve in Tuba, Benguet Northern Philippines | E8: G.M. Alfonso | F8: Journal | G8: Israel Journal of Ecology and Evolution | H8: Clarivate (Web of Science -SCIE); Scopus from 2006 to present | I8: birds diversity; richness; evenness; abundance; listing; eco class; endemism; species composition; conservation status | J8: https://doi.org/10.1163/22244662-bja10053
A9: 8 | B9: Jan-June 2023 | C9: CPAG | D9: Developing Finance Strategies: A Narrative on Financial Behavior of a State University Employees | E9: Glorina C. Damong | F9: Journal | G9: International Journal For Multidisciplinary Research | H9: open access peer-reviewed | I9: Financial Behavior, Finance Strategies, Employees | J9: https://www.ijfmr.com/research-paper.php?id=2072
A10: 9 | B10: Jan-June 2023 | C10: CF | D10: Challenges of Retrieving LULC Information in Rural-Forest Mosaic Landscapes Using Random Forest Technique | E10: Chinsu Lin* and Nova D. Doyog | F10: Journal | G10: Forests 2023, 14(4), 816 | H10: Scopus/Clarivate | I10: forest classification; mapping; forest degradation; agriculture; machine learning; sustainability | J10: https://www.mdpi.com/1999-4907/14/4/816
A11: 10 | B11: Jan-June 2023 | C11: CN | D11: Water quality, plankton community and primary productivity of Langiran Lake in Bayambang, Pangasinan, Philippines | E11: Mendoza, Dante M; Aquino, Michelle G B; Tandoc, Mark P; Briñas, Karen B B; Reyes, Doname A; et al. | F11: Journal | G11: AACL Bioflux, 2023, Volume 16, Issue 2. | H11: Scopus | I11: eutrophication, Langiran Lake, phytoplankton, trophic status, zooplankton. | J11: https://www.proquest.com/openview/40c750d5a62fadda32c139bc24378005/1?pq-origsite=gscholar&cbl=2046424
A12: 11 | B12: Jan-June 2023 | C12: CNS | D12: Principal components of students’ difficulties in mathematics in the purview of flexible learning | E12: Sibaen, N. W., Buasen, J. A., & Alimondo, M. S. | F12: Journal | G12: Journal on Mathematics Education, 14(2), 353–37 | H12: Scopus | I12: Flexible LearningMathematicsPrincipal Component AnalysisStudents’ Difficulties | J12: https://doi.org/10.22342/jme.v14i2.pp353-374
A13: 12 | B13: Jan-June 2023 | C13: CNS | D13: Plant Diversity in Selected Agro- and Forest Ecosystems in Indigenous Cultural Communities (ICCs) in the Cordillera Region, Northern Philippines | E13: Romeo A. Gomez Jr, Jason M. Leung, Joyce N. Paing, Elizabeth T. Dom-ogen, Aldrin V. Baniaga & Rey D. Napoleon | F13: Book | G13: Plant Diversity in Biocultural Landscapes | H13: Springer | I13: Indigenous cultural communities (ICCs) Traditional rice-based ecosystems (TRBEs) UNESCO World Heritage GIAHS SEPL Satoyama-satoumi Protected areas Communal | J13: https://link.springer.com/chapter/10.1007/978-981-19-8649-9_22
... A17: 15 | B17: Jan-June 2023 | C17: CAH | D17: Assessment of the Implementation of Mother Tongue Based -Multilingual Education in Benguet | E17: Dominga S. Tomas | F17: Journal | G17: E-DAWA: An International Multidisciplinary Research Journal Volume 3 I Issue 1 I May 2023 | H17: open access peer-reviewed | I17: pagtataya, MTB-MLE, implementasyon, unang wika | J17: https://doi.org/10.56901/FKAE5866
A18: 16 | B18: Jan-June 2023 | D18: Thriving Women After Marital Separation: A Case Study | E18: Erlyn Honeylette C Marquez, Cecilia G Junio | F18: Journal | G18: PSU Journal of Advanced Studies | H18: open access peer-reviewed | I18: Separated Married Women, Thriving Experiences, Challenges, Coping Techniques, Counseling Techniques | J18: https://www.psurj.org/online/index.php/jas/article/view/257
A19: 17 | B19: Jan-June 2023 | C19: CNS | D19: Intensities of human disturbance dictate the floral diversity in tropical forest: the case of a secondary forest in Benguet, Philippines | E19: Domelson A. Balangen, Melchor S. Catones, Jane M. Bayeng & Jones T. Napaldet | F19: Journal | G19: Journal of Mountain Science | H19: Scopus from 2007-2024, Web of Science-SCIE | I19: Land use change Secondary forest Conventional farming Endemic species Exotic species | J19: https://link.springer.com/article/10.1007/s11629-022-7830-7
A20: 18 | B20: Jan-June 2023 | C20: CA | D20: Performance of Seed-Primed Ricebean (Vigna umbellata L.) Using Organic-Based Priming Materials and Priming Duration | E20: Hector C. Gayomba, Belinda A. Tad-awan, Hilda V. Palaes, and Juniel S. Busiguit | F20: Journal | G20: Mountain Journal of Science and Interdisciplinary Research 83 No. 1 | H20: Scopus | I20: organic-based priming materials, seed priming, priming duration, ricebean | J20: http://portal.bsu.edu.ph:8083/index.php/BRJ/article/view/353
A21: 19 | B21: Jan-June 2023 | C21: CHET | D21: Development of Berry-Flavored Lemongrass Herbal Tea | E21: Kathlyn P. Aragon and Jao-jao A. Somyden | F21: Journal | G21: Mountain Journal of Science and Interdisciplinary Research 83 No. 1 | H21: Scopus | I21: Lemongrass, Strawberry, Mulberry, Herbal tea | J21: http://portal.bsu.edu.ph:8083/index.php/BRJ/article/view/354
A22: 20 | B22: Jan-June 2023 | C22: CTE | D22: Direct or Inquiry? Science Teaching Orientations of Prospective Secondary Science Teachers | E22: Apler J. Bansiong | F22: Journal | G22: Mountain Journal of Science and Interdisciplinary Research 83 No. 1 | H22: Scopus | I22: Science teaching orientation, Epistemic modes, Inquiry instruction, Direct teaching, Didactic direct, Guided inquiry, Open Inquiry | J22: http://portal.bsu.edu.ph:8083/index.php/BRJ/article/view/355
A23: 22 | B23: Jan-June 2023 | C23: Outside Contributor | D23: Technology Leadership and Technology Integration in Selected Science High Schools in the National Capital Region: Basis for a Proposed Online Training Module | E23: Rafael V. Panganiban | F23: Journal | G23: Mountain Journal of Science and Interdisciplinary Research 83 No. 1 | H23: Scopus | I23: Education 4.0, International Technology Standards, Online Training, Technology Integration, Technology Leadership
A24: 21 | B24: Jan-June 2023 | C24: CSS | D24: Flexible Learning Opportunities and Challenges: Exploring the Experiences of Benguet State University During the COVID-19 Pandemic | E24: Ma. Theresa B. Dolipas, Karryl Mae C. Ngina, and Gigy G. Banes | F24: Journal | G24: Mountain Journal of Science and Interdisciplinary Research 83 No. 1 | H24: Scopus | I24: flexible learning, flexible learning challenges, flexible learning coping mechanisms, flexible learning opportunities | J24: http://portal.bsu.edu.ph:8083/index.php/BRJ/article/view/357
A25: 22 | B25: Jan-June 2023 | C25: NPRCRTC | D25: Documentation and Promotion of Using Minisett Technique in Seed Yam Production | E25: Dalen T. Meldoz, Violeta B. Salda, and Grace S. Backian | F25: Journal | G25: Mountain Journal of Science and Interdisciplinary Research 83 No. 1 | H25: Scopus | I25: yam minisett technique, seed yam, productivity, documentation | J25: http://portal.bsu.edu.ph:8083/index.php/BRJ/article/view/358
A26: 25 | B26: Jan-June 2023 | C26: Outside Contributor | D26: Market Chain Analysis of White Corn in Abra | E26: Jovinia S. Lucas | F26: Journal | G26: Mountain Journal of Science and Interdisciplinary Research 83 No. 1 | H26: Scopus | I26: market chain analysis, market chain, white corn, Abra
A27: 23 | B27: Jan-June 2023 | C27: CAH | D27: Strategic Competences of Local Tourist Guides | E27: Richard A. Giye and Jhordan T. Cuilan | F27: Journal | G27: Mountain Journal of Science and Interdisciplinary Research 83 No. 1 | H27: Scopus | I27: Strategic, Tour guides, Communication breakdown | J27: http://portal.bsu.edu.ph:8083/index.php/BRJ/article/view/360
A28: 24 | B28: Jan-June 2023 | C28: CSS | D28: Parenting Too Soon: Education and Child Care Concerns of College Student Mothers in the Cordillera Administrative Region | E28: Ann Heather B. Kiwang, Mursha D. Gapasin, and Gigy G. Banes | F28: Journal | G28: Mountain Journal of Science and Interdisciplinary Research 83 No. 1 | H28: Scopus | I28: Teenage pregnancy, Student mothers, Child care | J28: http://portal.bsu.edu.ph:8083/index.php/BRJ/article/view/361
A29: 25 | B29: Jan-June 2023 | C29: BSU Buguias | D29: Working Relationship Practices Between Administrators and Teachers: Effects on Teachers’ Job Performance | E29: Neivalyn B. Labenio | F29: Journal | G29: Mountain Journal of Science and Interdisciplinary Research 83 No. 1 | H29: Scopus | I29: Administrators, Teachers, Working relationship practices, Job performance | J29: http://portal.bsu.edu.ph:8083/index.php/BRJ/article/view/362
A30: 26 | B30: July - Dec 2023 | C30: CF | D30: Biodiversity Conservation in Mining Landscapes: a Systematic Review of Assessment Approaches in the Philippines | E30: Bernard Peter O. Daipan, Crusty E. Tinio, Nelson M. Pampolina | F30: Journal | G30: Philippine Journal of Science | H30: SCOPUS | I30: biodiversity, conservation, mining area, mineral production sharing agreement | J30: https://doi.org/10.56899/152.04.15
A31: 27 | B31: July - Dec 2023 | C31: CF | D31: Mapping Forest Vulnerability to Fire and Landslides in the Cordillera Region, Philippines | E31: Bernard Peter O. Daipan, Diomedes A. Racelis | F31: Journal | G31: Science and Engineering Journal (SCIENGGJ) | H31: SCOPUS/ Clarivate/ Web of Science (ISI) | I31: Cordillera, Forest Fire, GIS, Landslide, Vulnerability | J31: https://scienggj.org/2023-265/
A32: 28 | B32: July - Dec 2023 | C32: CIS | D32: Opportunities and limitations to social learning for sustainability: empirical insights from a participatory approach to community-based resource management in the Philippines | E32: Doreen Ingosan Allasiw,Toshinori Tanaka,Shogo Kudo &Takashi Mino | F32: Journal | G32: International Journal of Agricultural Sustainability | H32: SCOPUS/Clarivate/Web of Science (ISI) | I32: Participatory Approach; Social Learning; Sustainability; Community-based Irrigation Management; Institutions; Collective Action; Conflict Resolution | J32: https://doi.org/10.1080/14735903.2023.2239075
A33: 29 | B33: July - Dec 2023 | C33: CNS | D33: Plant species and ecosystem diversity along national road in mountain sites: The case of Kennon Road in Cordillera Central Range, Philippines | E33: Jones T. Napaldet | F33: Journal | G33: Taiwania | H33: SCOPUS/ Clarivate/ Web of Science (ISI) | I33: Conservation-important species, Kennon Road, Neotropical element, road biodiversity, Shannon diversity | J33: https://www.researchgate.net/profile/Jones-Napaldet/publication/373556574_Plant_species_and_ecosystem_diversity_along_national_road_in_mountain_sites_The_case_of_Kennon_Road_in_Cordillera_Central_Range_Philippines/links/64f1b91bc40f1d22df82ef02/Plant-species-and-ecosystem-diversity-along-national-road-in-mountain-sites-The-case-of-Kennon-Road-in-Cordillera-Central-Range-Philippines.pdf
A34: 30 | B34: July - Dec 2023 | C34: ULIS | D34: Gender Inclusivity of Library and Information Services | E34: Daniel S. Balbin, Jr. | F34: Journal | G34: PAARL Research Journal PRJ 2023; Vol. 9: 84-110 | H34: open access peer-reviewed | I34: Library services, library inclusivity, gender inclusivity, Library Bill of Rights, LGBTQIA+ | J34: https://www.ejournals.ph/article.php?id=20041
A35: 31 | B35: July - Dec 2023 | C35: ULIS | D35: Virtual Internship Experiences of Library and Information Science Students During the Pandemic | E35: Daniel Jr. Soriano Balbin, Russell Battad Dolendo | F35: Journal | G35: Journal of Information Science Theory and Practice | H35: Scopus | I35: library schools, in-service training, library science, models, educational | J35: https://doi.org/10.1633/JISTaP.2023.11.3.5
A36: 32 | B36: July - Dec 2023 | C36: CAH | D36: EXAMINING THE IMPACT OF SINGLE PARENTING ON THE ACADEMIC PERFORMANCE OF JUNIOR HIGH SCHOOL STUDENTS | E36: Aubrae Frances Engngeg Bannawi, Novia Praise Dewanan Foy-awen, Amir Sam Tagtag Joseph, Glayrheal Ducas Del Rosario, Lester Lyle Dayasen Andawi, Nover Luke Dalog Eslao, Ashlyn Jace Lagasca Banih, John Rey Osben Pelila | F36: Journal | G36: INTERNATIONAL JOURNAL OF EDUCATION, PSYCHOLOGY AND COUNSELLING | H36: open access peer-reviewed | I36: Single Parenting, Academic Performance, Junior High School Students, Correlational Study | J36: https://www.researchgate.net/profile/John-Rey-Pelila/publication/374006074_Examining_the_Impact_of_Single_Parenting_on_the_Academic_Performance_of_Junior_High_School_Students/links/65096d3382f01628f0310534/Examining-the-Impact-of-Single-Parenting-on-the-Academic-Performance-of-Junior-High-School-Students.pdf
A37: 33 | B37: July - Dec 2023 | C37: CF | D37: Phylogenetic relationships and historical biogeography of Otus species based on mitochondrial cytochrome b gene sequence | E37: Bernard Peter O. Daipan, Ivy Amor F. Lambio, Juan Carlos T. Gonzales, Nelson M. Pampolina | F37: Journal | G37: Israel Journal of Ecology and Evolution | H37: SCOPUS/ Clarivet / Web of Science (ISI) | I37: Bayesian; biogeography; Maximum Likelihood; Maximum Parsimony; Otus; phylogeny | J37: https://doi.org/10.1163/22244662-bja10062
A38: 34 | B38: July - Dec 2023 | C38: CHK | D38: Motivation and Effects of Adventure Sports Tourism in the Cordillera Administrative Region, Philippines | E38: Harland Gary B. Pawid | F38: Journal | G38: CONNEXION Journal of Humanities and Social Sciences, 12(2), | H38: open access peer-reviewed | I38: Adventure Sports Tourism, Environmental Awareness, Nature, Culture, Sustainable Tourism Development | J38: https://so05.tci-thaijo.org/index.php/MFUconnexion/article/view/266494/180114
... A45: 40 | B45: July - Dec 2023 | C45: CNS | D45: Morpho-Anatomy and Mathematical Modelling in Lilium philippinense Baker from Cordillera Central Range, Philippines | E45: Jennifer C. Paltiyan-Bugtong, Rey G. Lumpio, Jones T. Napaldet, | F45: Journal | G45: Trop Life Sci Res. 2023 Sep; 34(3): 217–235 | H45: Scopus from 2009 to 2023/ Clarivate (Emerging Sources Citation Index) | I45: Monocot Plant with Dicot Characters, Lilium philippinense, Lilium formosanum, Correlation, Regression | J45: https://doi.org/10.21315%2Ftlsr2023.34.3.12
A46: 41 | B46: July - Dec 2023 | C46: CF/GIS | D46: Land Use and Land Cover (LULC) Assessment within the Batanes Protected Landscapes and Seascapes. | E46: Doyog, Nova D.; Lumbres, Roscinto Ian C.; Talkasen, Lynn J.; Soriano, Deign Frolley C. | F46: Journal | G46: Philippine Journal of Science, 2023, Vol 152, Issue 5, p1753 | H46: Web of Science - Zoological Records; Scopus from 2009 to 2024 | J46: https://www.researchgate.net/profile/Roscinto-Ian-Lumbres/publication/374343068_Land_Use_and_Land_Cover_LULC_Assessment_within_the_Batanes_Protected_Landscapes_and_Seascapes/links/654f3d2ace88b87031de9040/Land-Use-and-Land-Cover-LULC-Assessment-within-the-Batanes-Protected-Landscapes-and-Seascapes.pdf
A47: 42 | B47: July - Dec 2023 | C47: CN | D47: Research Knowledge Transfer in the Nursing Education Colleges of two Selected State Universities in Luzon (Philippines) | E47: Brian Saludes Bantugan, Jonalyn Esco, Chevelle ValencianoGaan, and Denice Mikaela Navarro | F47: Journal | G47: International Journal of Arts and Social Science Volume 6 Issue 3, | H47: open access peer-reviewed | I47: Research, Research Knowledge, Knowledge Transfer, State Universities and Colleges, Nursing Education Research | J47: https://www.researchgate.net/profile/Brian-Bantugan/publication/369289239_Research_Knowledge_Transfer_in_the_Nursing_Education_Colleges_of_two_Selected_State_Universities_in_Luzon_Philippines/links/6413242392cfd54f84061ac7/Research-Knowledge-Transfer-in-the-Nursing-Education-Colleges-of-two-Selected-State-Universities-in-Luzon-Philippines.pdf
A48: 43 | B48: July - Dec 2023 | C48: CF | D48: Urban Forest Cover and LST Change Monitoring Through Optical and Thermal Remote Sensing Approach | E48: Nova D. Doyog | F48: Journal | G48: Journal of the Indian Society of Remote Sensing Volume 51, pages 2467–2480 | H48: Clarivate (Science Citation Index Expanded)/Scopus from 1973 to Present | I48: Image enhancement, Optical and thermal multi-temporal data, Urban forest degradation, Urban temperature | J48: https://link.springer.com/article/10.1007/s12524-023-01779-w
